Workbook

Sheet Instructions
A1: Cost Breakdown & Unit Rate Analysis Workbook
A2: Norden Trading Plc | Build unit rates from material, labour and equipment prices
A4: HOW TO USE
A5: 1. 'Resources' sheet: update the prices of materials, labour and equipment to today's market prices. The yellow-shaded example prices are ILLUSTRATIONS ONLY — replace every one.
A6: 2. 'Rate Analysis' sheet: each block builds one BOQ item. Set the 'Qty per unit' coefficients to match your mix design / site norms (the sample coefficients are typical starting values, not a standard).
A7: 3. Overhead % and Profit % are set once at the top of 'Rate Analysis' and apply to every block.
A8: 4. 'Unit Rates' lists the final rate of every block. Copy those rates into your BOQ.
A9: 5. To add an item: copy a whole block, paste it below the last block, and change the title, unit and resource codes.
A10: 6. To add a resource: add a new row at the bottom of 'Resources' with a unique code, then use that code in a block.
A12: COLOUR CODE: Blue text on a pale-yellow cell = you type here. Black = formula.
A14: NOTE: Coefficients, wastage and prices vary by project, specification and supplier. This workbook is a calculation framework — it does not replace professional judgment.

Sheet Resources
A1: Resources — Material, Labour & Equipment Prices
A2: Replace the example prices with current market prices (ETB)
A4: Code | B4: Type | C4: Description | D4: Unit | E4: Base price (ETB) | F4: Wastage % | G4: Effective price (ETB)
A5: M-001 | B5: Material | C5: Cement, 50 kg bag | D5: bag | E5: 950 | F5: 0.03 | G5: =E5*(1+F5) -> 978.5
A6: M-002 | B6: Material | C6: Sand (river / washed) | D6: m3 | E6: 2200 | F6: 0.05 | G6: =E6*(1+F6) -> 2310
A7: M-003 | B7: Material | C7: Coarse aggregate 20 mm | D7: m3 | E7: 2600 | F7: 0.05 | G7: =E7*(1+F7) -> 2730
A8: M-004 | B8: Material | C8: Reinforcement steel bars | D8: kg | E8: 95 | F8: 0.05 | G8: =E8*(1+F8) -> 99.75
A9: M-005 | B9: Material | C9: Binding wire | D9: kg | E9: 110 | F9: 0.05 | G9: =E9*(1+F9) -> 115.5
A10: M-006 | B10: Material | C10: Hollow concrete block 20 cm | D10: no | E10: 38 | F10: 0.03 | G10: =E10*(1+F10) -> 39.14
A11: M-007 | B11: Material | C11: Timber for formwork (use-adjusted) | D11: m2 | E11: 350 | F11: 0 | G11: =E11*(1+F11) -> 350
A12: M-008 | B12: Material | C12: Ceramic floor tile | D12: m2 | E12: 850 | F12: 0.07 | G12: =E12*(1+F12) -> 909.5
A13: M-009 | B13: Material | C13: Tile adhesive, 25 kg bag | D13: bag | E13: 420 | F13: 0.03 | G13: =E13*(1+F13) -> 432.6
A14: M-010 | B14: Material | C14: Emulsion paint, 20 L | D14: L | E14: 4800 | F14: 0.05 | G14: =E14*(1+F14) -> 5040
A15: M-011 | B15: Material | C15: Plaster primer / sealer | D15: L | E15: 3200 | F15: 0.05 | G15: =E15*(1+F15) -> 3360
A16: M-012 | B16: Material | C16: Water | D16: m3 | E16: 120 | F16: 0 | G16: =E16*(1+F16) -> 120
... A26: E-003 | B26: Equipment | C26: Scaffolding (hire) | D26: m2/day | E26: 15 | F26: 0 | G26: =E26*(1+F26) -> 15
G27: =IF(E27="","",E27*(1+F27))
G28: =IF(E28="","",E28*(1+F28))
G29: =IF(E29="","",E29*(1+F29))
G30: =IF(E30="","",E30*(1+F30))
G31: =IF(E31="","",E31*(1+F31))
G32: =IF(E32="","",E32*(1+F32))
G33: =IF(E33="","",E33*(1+F33))
G34: =IF(E34="","",E34*(1+F34))
G35: =IF(E35="","",E35*(1+F35))
G36: =IF(E36="","",E36*(1+F36))
G37: =IF(E37="","",E37*(1+F37))
G38: =IF(E38="","",E38*(1+F38))
... G41: =IF(E41="","",E41*(1+F41))

Sheet Rate Analysis
A1: Unit Rate Analysis
A2: Qty per unit = how much of the resource is needed to produce ONE unit of the item
A3: Overhead % | C3: 0.1 | E3: Overhead and profit are applied to the direct cost of every block below.
A4: Profit % | C4: 0.1
A6: A. Concrete C-25, mixed on site and placed | F6: Unit: | G6: m3
A7: Code | B7: Description | C7: Unit | D7: Qty per unit | E7: Rate (ETB) | F7: Amount (ETB) | G7: Type
A8: M-001 | B8: =IFERROR(INDEX(Resources!$C$5:$C$42,MATCH(A8,Resources!$A$5:$A$42,0)),"") -> Cement, 50 kg bag | C8: =IFERROR(INDEX(Resources!$D$5:$D$42,MATCH(A8,Resources!$A$5:$A$42,0)),"") -> bag | D8: 7 | E8: =IFERROR(INDEX(Resources!$G$5:$G$42,MATCH(A8,Resources!$A$5:$A$42,0)),0) -> 978.5 | F8: =D8*E8 -> 6849.5 | G8: =IFERROR(INDEX(Resources!$B$5:$B$42,MATCH(A8,Resources!$A$5:$A$42,0)),"") -> Material
A9: M-002 | B9: =IFERROR(INDEX(Resources!$C$5:$C$42,MATCH(A9,Resources!$A$5:$A$42,0)),"") -> Sand (river / washed) | C9: =IFERROR(INDEX(Resources!$D$5:$D$42,MATCH(A9,Resources!$A$5:$A$42,0)),"") -> m3 | D9: 0.45 | E9: =IFERROR(INDEX(Resources!$G$5:$G$42,MATCH(A9,Resources!$A$5:$A$42,0)),0) -> 2310 | F9: =D9*E9 -> 1039.5 | G9: =IFERROR(INDEX(Resources!$B$5:$B$42,MATCH(A9,Resources!$A$5:$A$42,0)),"") -> Material
A10: M-003 | B10: =IFERROR(INDEX(Resources!$C$5:$C$42,MATCH(A10,Resources!$A$5:$A$42,0)),"") -> Coarse aggregate 20 mm | C10: =IFERROR(INDEX(Resources!$D$5:$D$42,MATCH(A10,Resources!$A$5:$A$42,0)),"") -> m3 | D10: 0.85 | E10: =IFERROR(INDEX(Resources!$G$5:$G$42,MATCH(A10,Resources!$A$5:$A$42,0)),0) -> 2730 | F10: =D10*E10 -> 2320.5 | G10: =IFERROR(INDEX(Resources!$B$5:$B$42,MATCH(A10,Resources!$A$5:$A$42,0)),"") -> Material
A11: M-012 | B11: =IFERROR(INDEX(Resources!$C$5:$C$42,MATCH(A11,Resources!$A$5:$A$42,0)),"") -> Water | C11: =IFERROR(INDEX(Resources!$D$5:$D$42,MATCH(A11,Resources!$A$5:$A$42,0)),"") -> m3 | D11: 0.18 | E11: =IFERROR(INDEX(Resources!$G$5:$G$42,MATCH(A11,Resources!$A$5:$A$42,0)),0) -> 120 | F11: =D11*E11 -> 21.6 | G11: =IFERROR(INDEX(Resources!$B$5:$B$42,MATCH(A11,Resources!$A$5:$A$42,0)),"") -> Material
A12: L-002 | B12: =IFERROR(INDEX(Resources!$C$5:$C$42,MATCH(A12,Resources!$A$5:$A$42,0)),"") -> Mason | C12: =IFERROR(INDEX(Resources!$D$5:$D$42,MATCH(A12,Resources!$A$5:$A$42,0)),"") -> day | D12: 0.5 | E12: =IFERROR(INDEX(Resources!$G$5:$G$42,MATCH(A12,Resources!$A$5:$A$42,0)),0) -> 800 | F12: =D12*E12 -> 400 | G12: =IFERROR(INDEX(Resources!$B$5:$B$42,MATCH(A12,Resources!$A$5:$A$42,0)),"") -> Labour
A13: L-007 | B13: =IFERROR(INDEX(Resources!$C$5:$C$42,MATCH(A13,Resources!$A$5:$A$42,0)),"") -> Unskilled labourer | C13: =IFERROR(INDEX(Resources!$D$5:$D$42,MATCH(A13,Resources!$A$5:$A$42,0)),"") -> day | D13: 2.5 | E13: =IFERROR(INDEX(Resources!$G$5:$G$42,MATCH(A13,Resources!$A$5:$A$42,0)),0) -> 450 | F13: =D13*E13 -> 1125 | G13: =IFERROR(INDEX(Resources!$B$5:$B$42,MATCH(A13,Resources!$A$5:$A$42,0)),"") -> Labour
A14: E-001 | B14: =IFERROR(INDEX(Resources!$C$5:$C$42,MATCH(A14,Resources!$A$5:$A$42,0)),"") -> Concrete mixer (hire) | C14: =IFERROR(INDEX(Resources!$D$5:$D$42,MATCH(A14,Resources!$A$5:$A$42,0)),"") -> hr | D14: 1.5 | E14: =IFERROR(INDEX(Resources!$G$5:$G$42,MATCH(A14,Resources!$A$5:$A$42,0)),0) -> 350 | F14: =D14*E14 -> 525 | G14: =IFERROR(INDEX(Resources!$B$5:$B$42,MATCH(A14,Resources!$A$5:$A$42,0)),"") -> Equipment
A15: E-002 | B15: =IFERROR(INDEX(Resources!$C$5:$C$42,MATCH(A15,Resources!$A$5:$A$42,0)),"") -> Poker vibrator (hire) | C15: =IFERROR(INDEX(Resources!$D$5:$D$42,MATCH(A15,Resources!$A$5:$A$42,0)),"") -> hr | D15: 1 | E15: =IFERROR(INDEX(Resources!$G$5:$G$42,MATCH(A15,Resources!$A$5:$A$42,0)),0) -> 200 | F15: =D15*E15 -> 200 | G15: =IFERROR(INDEX(Resources!$B$5:$B$42,MATCH(A15,Resources!$A$5:$A$42,0)),"") -> Equipment
B16: =IFERROR(INDEX(Resources!$C$5:$C$42,MATCH(A16,Resources!$A$5:$A$42,0)),"") | C16: =IFERROR(INDEX(Resources!$D$5:$D$42,MATCH(A16,Resources!$A$5:$A$42,0)),"") | E16: =IFERROR(INDEX(Resources!$G$5:$G$42,MATCH(A16,Resources!$A$5:$A$42,0)),0) -> 0 | F16: =D16*E16 -> 0 | G16: =IFERROR(INDEX(Resources!$B$5:$B$42,MATCH(A16,Resources!$A$5:$A$42,0)),"")
B17: =IFERROR(INDEX(Resources!$C$5:$C$42,MATCH(A17,Resources!$A$5:$A$42,0)),"") | C17: =IFERROR(INDEX(Resources!$D$5:$D$42,MATCH(A17,Resources!$A$5:$A$42,0)),"") | E17: =IFERROR(INDEX(Resources!$G$5:$G$42,MATCH(A17,Resources!$A$5:$A$42,0)),0) -> 0 | F17: =D17*E17 -> 0 | G17: =IFERROR(INDEX(Resources!$B$5:$B$42,MATCH(A17,Resources!$A$5:$A$42,0)),"")
E18: Direct cost | F18: =SUM(F8:F17) -> 12481.1
E19: Overhead | F19: =F18*$C$3 -> 1248.11
E20: Profit | F20: =(F18+F19)*$C$4 -> 1372.921
E21: UNIT RATE | F21: =F18+F19+F20 -> 15102.131
A24: B. Reinforcement steel, supply, cut, bend and fix | F24: Unit: | G24: kg
A25: Code | B25: Description | C25: Unit | D25: Qty per unit | E25: Rate (ETB) | F25: Amount (ETB) | G25: Type
A26: M-004 | B26: =IFERROR(INDEX(Resources!$C$5:$C$42,MATCH(A26,Resources!$A$5:$A$42,0)),"") -> Reinforcement steel bars | C26: =IFERROR(INDEX(Resources!$D$5:$D$42,MATCH(A26,Resources!$A$5:$A$42,0)),"") -> kg | D26: 1 | E26: =IFERROR(INDEX(Resources!$G$5:$G$42,MATCH(A26,Resources!$A$5:$A$42,0)),0) -> 99.75 | F26: =D26*E26 -> 99.75 | G26: =IFERROR(INDEX(Resources!$B$5:$B$42,MATCH(A26,Resources!$A$5:$A$42,0)),"") -> Material
A27: M-005 | B27: =IFERROR(INDEX(Resources!$C$5:$C$42,MATCH(A27,Resources!$A$5:$A$42,0)),"") -> Binding wire | C27: =IFERROR(INDEX(Resources!$D$5:$D$42,MATCH(A27,Resources!$A$5:$A$42,0)),"") -> kg | D27: 0.012 | E27: =IFERROR(INDEX(Resources!$G$5:$G$42,MATCH(A27,Resources!$A$5:$A$42,0)),0) -> 115.5 | F27: =D27*E27 -> 1.386 | G27: =IFERROR(INDEX(Resources!$B$5:$B$42,MATCH(A27,Resources!$A$5:$A$42,0)),"") -> Material
A28: L-004 | B28: =IFERROR(INDEX(Resources!$C$5:$C$42,MATCH(A28,Resources!$A$5:$A$42,0)),"") -> Steel fixer | C28: =IFERROR(INDEX(Resources!$D$5:$D$42,MATCH(A28,Resources!$A$5:$A$42,0)),"") -> day | D28: 0.012 | E28: =IFERROR(INDEX(Resources!$G$5:$G$42,MATCH(A28,Resources!$A$5:$A$42,0)),0) -> 750 | F28: =D28*E28 -> 9 | G28: =IFERROR(INDEX(Resources!$B$5:$B$42,MATCH(A28,Resources!$A$5:$A$42,0)),"") -> Labour
A29: L-007 | B29: =IFERROR(INDEX(Resources!$C$5:$C$42,MATCH(A29,Resources!$A$5:$A$42,0)),"") -> Unskilled labourer | C29: =IFERROR(INDEX(Resources!$D$5:$D$42,MATCH(A29,Resources!$A$5:$A$42,0)),"") -> day | D29: 0.012 | E29: =IFERROR(INDEX(Resources!$G$5:$G$42,MATCH(A29,Resources!$A$5:$A$42,0)),0) -> 450 | F29: =D29*E29 -> 5.4 | G29: =IFERROR(INDEX(Resources!$B$5:$B$42,MATCH(A29,Resources!$A$5:$A$42,0)),"") -> Labour
B30: =IFERROR(INDEX(Resources!$C$5:$C$42,MATCH(A30,Resources!$A$5:$A$42,0)),"") | C30: =IFERROR(INDEX(Resources!$D$5:$D$42,MATCH(A30,Resources!$A$5:$A$42,0)),"") | E30: =IFERROR(INDEX(Resources!$G$5:$G$42,MATCH(A30,Resources!$A$5:$A$42,0)),0) -> 0 | F30: =D30*E30 -> 0 | G30: =IFERROR(INDEX(Resources!$B$5:$B$42,MATCH(A30,Resources!$A$5:$A$42,0)),"")
B31: =IFERROR(INDEX(Resources!$C$5:$C$42,MATCH(A31,Resources!$A$5:$A$42,0)),"") | C31: =IFERROR(INDEX(Resources!$D$5:$D$42,MATCH(A31,Resources!$A$5:$A$42,0)),"") | E31: =IFERROR(INDEX(Resources!$G$5:$G$42,MATCH(A31,Resources!$A$5:$A$42,0)),0) -> 0 | F31: =D31*E31 -> 0 | G31: =IFERROR(INDEX(Resources!$B$5:$B$42,MATCH(A31,Resources!$A$5:$A$42,0)),"")
E32: Direct cost | F32: =SUM(F26:F31) -> 115.536
E33: Overhead | F33: =F32*$C$3 -> 11.5536
E34: Profit | F34: =(F32+F33)*$C$4 -> 12.70896
E35: UNIT RATE | F35: =F32+F33+F34 -> 139.79856
A38: C. Formwork to columns, beams and slabs (contact area) | F38: Unit: | G38: m2
A39: Code | B39: Description | C39: Unit | D39: Qty per unit | E39: Rate (ETB) | F39: Amount (ETB) | G39: Type
A40: M-007 | B40: =IFERROR(INDEX(Resources!$C$5:$C$42,MATCH(A40,Resources!$A$5:$A$42,0)),"") -> Timber for formwork (use-adjusted) | C40: =IFERROR(INDEX(Resources!$D$5:$D$42,MATCH(A40,Resources!$A$5:$A$42,0)),"") -> m2 | D40: 1 | E40: =IFERROR(INDEX(Resources!$G$5:$G$42,MATCH(A40,Resources!$A$5:$A$42,0)),0) -> 350 | F40: =D40*E40 -> 350 | G40: =IFERROR(INDEX(Resources!$B$5:$B$42,MATCH(A40,Resources!$A$5:$A$42,0)),"") -> Material
A41: L-003 | B41: =IFERROR(INDEX(Resources!$C$5:$C$42,MATCH(A41,Resources!$A$5:$A$42,0)),"") -> Carpenter | C41: =IFERROR(INDEX(Resources!$D$5:$D$42,MATCH(A41,Resources!$A$5:$A$42,0)),"") -> day | D41: 0.35 | E41: =IFERROR(INDEX(Resources!$G$5:$G$42,MATCH(A41,Resources!$A$5:$A$42,0)),0) -> 800 | F41: =D41*E41 -> 280 | G41: =IFERROR(INDEX(Resources!$B$5:$B$42,MATCH(A41,Resources!$A$5:$A$42,0)),"") -> Labour
A42: L-007 | B42: =IFERROR(INDEX(Resources!$C$5:$C$42,MATCH(A42,Resources!$A$5:$A$42,0)),"") -> Unskilled labourer | C42: =IFERROR(INDEX(Resources!$D$5:$D$42,MATCH(A42,Resources!$A$5:$A$42,0)),"") -> day | D42: 0.25 | E42: =IFERROR(INDEX(Resources!$G$5:$G$42,MATCH(A42,Resources!$A$5:$A$42,0)),0) -> 450 | F42: =D42*E42 -> 112.5 | G42: =IFERROR(INDEX(Resources!$B$5:$B$42,MATCH(A42,Resources!$A$5:$A$42,0)),"") -> Labour
B43: =IFERROR(INDEX(Resources!$C$5:$C$42,MATCH(A43,Resources!$A$5:$A$42,0)),"") | C43: =IFERROR(INDEX(Resources!$D$5:$D$42,MATCH(A43,Resources!$A$5:$A$42,0)),"") | E43: =IFERROR(INDEX(Resources!$G$5:$G$42,MATCH(A43,Resources!$A$5:$A$42,0)),0) -> 0 | F43: =D43*E43 -> 0 | G43: =IFERROR(INDEX(Resources!$B$5:$B$42,MATCH(A43,Resources!$A$5:$A$42,0)),"")
B44: =IFERROR(INDEX(Resources!$C$5:$C$42,MATCH(A44,Resources!$A$5:$A$42,0)),"") | C44: =IFERROR(INDEX(Resources!$D$5:$D$42,MATCH(A44,Resources!$A$5:$A$42,0)),"") | E44: =IFERROR(INDEX(Resources!$G$5:$G$42,MATCH(A44,Resources!$A$5:$A$42,0)),0) -> 0 | F44: =D44*E44 -> 0 | G44: =IFERROR(INDEX(Resources!$B$5:$B$42,MATCH(A44,Resources!$A$5:$A$42,0)),"")
E45: Direct cost | F45: =SUM(F40:F44) -> 742.5
...

Sheet Unit Rates
A1: Unit Rates Summary
A2: Copy these rates into the Rate column of your BOQ
A4: Item | B4: Unit | C4: Unit rate (ETB)
A5: A. Concrete C-25, mixed on site and placed | B5: m3 | C5: ='Rate Analysis'!F21 -> 15102.131
A6: B. Reinforcement steel, supply, cut, bend and fix | B6: kg | C6: ='Rate Analysis'!F35 -> 139.79856
A7: C. Formwork to columns, beams and slabs (contact area) | B7: m2 | C7: ='Rate Analysis'!F48 -> 898.425
A8: D. 20 cm hollow concrete block walling | B8: m2 | C8: ='Rate Analysis'!F64 -> 1516.6443
A9: E. Cement sand plaster, 2 coats, internal | B9: m2 | C9: ='Rate Analysis'!F79 -> 621.0567
A10: F. Ceramic floor tiling including adhesive | B10: m2 | C10: ='Rate Analysis'!F93 -> 1566.7903
A11: G. Emulsion paint, 3 coats, internal | B11: m2 | C11: ='Rate Analysis'!F107 -> 934.483
